<?xml version="1.0" ?>
<!-- =================================================================================== -->
<!-- |    This document was autogenerated by xacro from rrbot.xacro                    | -->
<!-- |    EDITING THIS FILE BY HAND IS NOT RECOMMENDED                                 | -->
<!-- =================================================================================== -->
<!-- Revolute-Revolute Manipulator -->
<robot name="rrbot">
  <!-- Space btw top of beam and the each joint -->
  <!-- Define colors -->
  <material name="black">
    <color rgba="0.0 0.0 0.0 1.0"/>
  </material>
  <material name="orange">
    <color rgba="1.0 0.4235294117647059 0.0392156862745098 1.0"/>
  </material>
  <!-- Used for fixing robot to Gazebo 'base_link' -->
  <link name="world"/>
  <joint name="fixed" type="fixed">
    <parent link="world"/>
    <child link="link1"/>
  </joint>
  <!-- Base Link -->
  <link name="link1">
    <collision>
      <origin rpy="0 0 0" xyz="0 0 1.0"/>
      <geometry>
        <box size="0.1 0.1 2"/>
      </geometry>
    </collision>
    <visual>
      <origin rpy="0 0 0" xyz="0 0 1.0"/>
      <geometry>
        <box size="0.1 0.1 2"/>
      </geometry>
      <material name="orange"/>
    </visual>
    <inertial>
      <origin rpy="0 0 0" xyz="0 0 1.0"/>
      <mass value="1"/>
      <inertia ixx="0.3341666666666666" ixy="0.0" ixz="0.0" iyy="0.3341666666666666" iyz="0.0" izz="0.001666666666666667"/>
    </inertial>
  </link>
  <joint name="joint1" type="continuous">
    <parent link="link1"/>
    <child link="link2"/>
    <origin rpy="0 0 0" xyz="0 0.1 1.95"/>
    <axis xyz="0 1 0"/>
    <dynamics damping="0.7"/>
  </joint>
  <!-- Middle Link -->
  <link name="link2">
    <collision>
      <origin rpy="0 0 0" xyz="0 0 0.45"/>
      <geometry>
        <box size="0.1 0.1 1"/>
      </geometry>
    </collision>
    <visual>
      <origin rpy="0 0 0" xyz="0 0 0.45"/>
      <geometry>
        <box size="0.1 0.1 1"/>
      </geometry>
      <material name="black"/>
    </visual>
    <inertial>
      <origin rpy="0 0 0" xyz="0 0 0.45"/>
      <mass value="1"/>
      <inertia ixx="0.08416666666666667" ixy="0.0" ixz="0.0" iyy="0.08416666666666667" iyz="0.0" izz="0.001666666666666667"/>
    </inertial>
  </link>
  <joint name="joint2" type="continuous">
    <parent link="link2"/>
    <child link="link3"/>
    <origin rpy="0 0 0" xyz="0 0.1 0.9"/>
    <axis xyz="0 1 0"/>
    <dynamics damping="0.7"/>
  </joint>
  <!-- Top Link -->
  <link name="link3">
    <collision>
      <origin rpy="0 0 0" xyz="0 0 0.45"/>
      <geometry>
        <box size="0.1 0.1 1"/>
      </geometry>
    </collision>
    <visual>
      <origin rpy="0 0 0" xyz="0 0 0.45"/>
      <geometry>
        <box size="0.1 0.1 1"/>
      </geometry>
      <material name="orange"/>
    </visual>
    <inertial>
      <origin rpy="0 0 0" xyz="0 0 0.45"/>
      <mass value="1"/>
      <inertia ixx="0.08416666666666667" ixy="0.0" ixz="0.0" iyy="0.08416666666666667" iyz="0.0" izz="0.001666666666666667"/>
    </inertial>
  </link>
  <!-- Gazebo colors and frictions -->
  <!-- Link1 -->
  <gazebo reference="link1">
    <material>
      <diffuse> 1 0.423529412 0.039215686 1</diffuse>
      <ambient> 1 0.423529412 0.039215686 1</ambient>
      <specular>1 0.423529412 0.039215686 1</specular>
    </material>
  </gazebo>
  <!-- Link2 -->
  <gazebo reference="link2">
    <mu1>0.2</mu1>
    <mu2>0.2</mu2>
    <material>
      <diffuse> 0 0 0 1</diffuse>
      <ambient> 0 0 0 1</ambient>
      <specular>0 0 0 1</specular>
    </material>
  </gazebo>
  <!-- Link3 -->
  <gazebo reference="link3">
    <mu1>0.2</mu1>
    <mu2>0.2</mu2>
    <material>
      <diffuse> 1 0.423529412 0.039215686 1</diffuse>
      <ambient> 1 0.423529412 0.039215686 1</ambient>
      <specular>1 0.423529412 0.039215686 1</specular>
    </material>
  </gazebo>
  <!-- Joint states plugin -->
  <gazebo>
    <plugin filename="gz-sim-joint-state-publisher-system" name="gz::sim::systems::JointStatePublisher"/>
  </gazebo>
</robot>
